2016-02-01 20:49:57,044::WARNING::base.py::182::[get_response(...)] :: Not Found: /validate/TXZUTKRS
2016-02-01 20:58:58,604::WARNING::base.py::182::[get_response(...)] :: Not Found: /validate/TXZUTKRS
2016-02-01 21:04:17,566::WARNING::base.py::182::[get_response(...)] :: Not Found: /sign-in/MTLMKYXA
2016-02-01 21:15:27,826::ERROR::base.py::284::[handle_uncaught_exception(...)] :: Internal Server Error: /
Traceback (most recent call last):
  File "//anaconda/lib/python2.7/site-packages/django/core/handlers/base.py", line 149, in get_response
    response = self.process_exception_by_middleware(e, request)
  File "//anaconda/lib/python2.7/site-packages/django/core/handlers/base.py", line 147, in get_response
    response = wrapped_callback(request, *callback_args, **callback_kwargs)
  File "/Users/kevindunn/Personal/Myself/Learn-Dutch/flashcards/vocab/views.py", line 233, in add_word_HTML
    add_new_word(part1, part2)
  File "/Users/kevindunn/Personal/Myself/Learn-Dutch/flashcards/vocab/views.py", line 201, in add_new_word
    part1 = part1.strip()
AttributeError: 'NoneType' object has no attribute 'strip'
2016-02-01 21:16:16,337::ERROR::base.py::284::[handle_uncaught_exception(...)] :: Internal Server Error: /
Traceback (most recent call last):
  File "//anaconda/lib/python2.7/site-packages/django/core/handlers/base.py", line 149, in get_response
    response = self.process_exception_by_middleware(e, request)
  File "//anaconda/lib/python2.7/site-packages/django/core/handlers/base.py", line 147, in get_response
    response = wrapped_callback(request, *callback_args, **callback_kwargs)
  File "/Users/kevindunn/Personal/Myself/Learn-Dutch/flashcards/vocab/views.py", line 232, in add_word_HTML
    if request.POST and person[0]:
  File "//anaconda/lib/python2.7/site-packages/django/db/models/query.py", line 297, in __getitem__
    return list(qs)[0]
IndexError: list index out of range
2016-02-01 21:37:18,734::WARNING::base.py::182::[get_response(...)] :: Not Found: //sign-in/TMUTSVNV
2016-02-01 21:37:26,632::WARNING::base.py::182::[get_response(...)] :: Not Found: /sign-in/TMUTSVNV
2016-02-01 21:38:10,029::WARNING::base.py::182::[get_response(...)] :: Not Found: /quiz
2016-02-01 21:38:14,338::ERROR::base.py::284::[handle_uncaught_exception(...)] :: Internal Server Error: /quiz/
Traceback (most recent call last):
  File "//anaconda/lib/python2.7/site-packages/django/core/handlers/base.py", line 149, in get_response
    response = self.process_exception_by_middleware(e, request)
  File "//anaconda/lib/python2.7/site-packages/django/core/handlers/base.py", line 147, in get_response
    response = wrapped_callback(request, *callback_args, **callback_kwargs)
  File "/Users/kevindunn/Personal/Myself/Learn-Dutch/flashcards/vocab/views.py", line 285, in quiz_HTML
    quiz.save()
  File "//anaconda/lib/python2.7/site-packages/django/db/models/base.py", line 700, in save
    force_update=force_update, update_fields=update_fields)
  File "//anaconda/lib/python2.7/site-packages/django/db/models/base.py", line 728, in save_base
    updated = self._save_table(raw, cls, force_insert, force_update, using, update_fields)
  File "//anaconda/lib/python2.7/site-packages/django/db/models/base.py", line 812, in _save_table
    result = self._do_insert(cls._base_manager, using, fields, update_pk, raw)
  File "//anaconda/lib/python2.7/site-packages/django/db/models/base.py", line 851, in _do_insert
    using=using, raw=raw)
  File "//anaconda/lib/python2.7/site-packages/django/db/models/manager.py", line 122, in manager_method
    return getattr(self.get_queryset(), name)(*args, **kwargs)
  File "//anaconda/lib/python2.7/site-packages/django/db/models/query.py", line 1039, in _insert
    return query.get_compiler(using=using).execute_sql(return_id)
  File "//anaconda/lib/python2.7/site-packages/django/db/models/sql/compiler.py", line 1060, in execute_sql
    cursor.execute(sql, params)
  File "//anaconda/lib/python2.7/site-packages/django/db/backends/utils.py", line 79, in execute
    return super(CursorDebugWrapper, self).execute(sql, params)
  File "//anaconda/lib/python2.7/site-packages/django/db/backends/utils.py", line 64, in execute
    return self.cursor.execute(sql, params)
  File "//anaconda/lib/python2.7/site-packages/django/db/utils.py", line 95, in __exit__
    six.reraise(dj_exc_type, dj_exc_value, traceback)
  File "//anaconda/lib/python2.7/site-packages/django/db/backends/utils.py", line 64, in execute
    return self.cursor.execute(sql, params)
  File "//anaconda/lib/python2.7/site-packages/django/db/backends/sqlite3/base.py", line 323, in execute
    return Database.Cursor.execute(self, query, params)
IntegrityError: NOT NULL constraint failed: vocab_quiz.person_id
2016-02-01 21:44:05,217::WARNING::base.py::182::[get_response(...)] :: Not Found: /quiz
2016-02-01 21:44:27,180::WARNING::base.py::182::[get_response(...)] :: Not Found: /quiz
2016-02-01 21:46:35,418::WARNING::base.py::182::[get_response(...)] :: Not Found: /quiz
2016-02-01 21:46:40,677::ERROR::base.py::284::[handle_uncaught_exception(...)] :: Internal Server Error: /quiz/BGYUESXL/
Traceback (most recent call last):
  File "//anaconda/lib/python2.7/site-packages/django/core/handlers/base.py", line 149, in get_response
    response = self.process_exception_by_middleware(e, request)
  File "//anaconda/lib/python2.7/site-packages/django/core/handlers/base.py", line 147, in get_response
    response = wrapped_callback(request, *callback_args, **callback_kwargs)
  File "/Users/kevindunn/Personal/Myself/Learn-Dutch/flashcards/vocab/views.py", line 376, in quiz_HTML
    return render(request, 'vocab/quiz.html', context)
  File "//anaconda/lib/python2.7/site-packages/django/shortcuts.py", line 67, in render
    template_name, context, request=request, using=using)
  File "//anaconda/lib/python2.7/site-packages/django/template/loader.py", line 96, in render_to_string
    template = get_template(template_name, using=using)
  File "//anaconda/lib/python2.7/site-packages/django/template/loader.py", line 32, in get_template
    return engine.get_template(template_name, dirs)
  File "//anaconda/lib/python2.7/site-packages/django/template/backends/django.py", line 40, in get_template
    return Template(self.engine.get_template(template_name, dirs), self)
  File "//anaconda/lib/python2.7/site-packages/django/template/engine.py", line 190, in get_template
    template, origin = self.find_template(template_name, dirs)
  File "//anaconda/lib/python2.7/site-packages/django/template/engine.py", line 157, in find_template
    name, template_dirs=dirs, skip=skip,
  File "//anaconda/lib/python2.7/site-packages/django/template/loaders/base.py", line 46, in get_template
    contents, origin, origin.template_name, self.engine,
  File "//anaconda/lib/python2.7/site-packages/django/template/base.py", line 189, in __init__
    self.nodelist = self.compile_nodelist()
  File "//anaconda/lib/python2.7/site-packages/django/template/base.py", line 230, in compile_nodelist
    return parser.parse()
  File "//anaconda/lib/python2.7/site-packages/django/template/base.py", line 514, in parse
    raise self.error(token, e)
TemplateSyntaxError: Invalid block tag on line 35: 'quiz.n_words_asked', expected 'endblock'. Did you forget to register or load this tag?
2016-02-01 22:01:01,314::ERROR::base.py::284::[handle_uncaught_exception(...)] :: Internal Server Error: /
Traceback (most recent call last):
  File "//anaconda/lib/python2.7/site-packages/django/core/handlers/base.py", line 149, in get_response
    response = self.process_exception_by_middleware(e, request)
  File "//anaconda/lib/python2.7/site-packages/django/core/handlers/base.py", line 147, in get_response
    response = wrapped_callback(request, *callback_args, **callback_kwargs)
  File "/Users/kevindunn/Personal/Myself/Learn-Dutch/flashcards/vocab/views.py", line 235, in add_word_HTML
    add_new_word(part1, part2)
  File "/Users/kevindunn/Personal/Myself/Learn-Dutch/flashcards/vocab/views.py", line 211, in add_new_word
    part2=part2)
  File "//anaconda/lib/python2.7/site-packages/django/db/models/manager.py", line 122, in manager_method
    return getattr(self.get_queryset(), name)(*args, **kwargs)
  File "//anaconda/lib/python2.7/site-packages/django/db/models/query.py", line 467, in get_or_create
    return self._create_object_from_params(lookup, params)
  File "//anaconda/lib/python2.7/site-packages/django/db/models/query.py", line 507, in _create_object_from_params
    six.reraise(*exc_info)
  File "//anaconda/lib/python2.7/site-packages/django/db/models/query.py", line 499, in _create_object_from_params
    obj = self.create(**params)
  File "//anaconda/lib/python2.7/site-packages/django/db/models/query.py", line 401, in create
    obj.save(force_insert=True, using=self.db)
  File "//anaconda/lib/python2.7/site-packages/django/db/models/base.py", line 700, in save
    force_update=force_update, update_fields=update_fields)
  File "//anaconda/lib/python2.7/site-packages/django/db/models/base.py", line 728, in save_base
    updated = self._save_table(raw, cls, force_insert, force_update, using, update_fields)
  File "//anaconda/lib/python2.7/site-packages/django/db/models/base.py", line 812, in _save_table
    result = self._do_insert(cls._base_manager, using, fields, update_pk, raw)
  File "//anaconda/lib/python2.7/site-packages/django/db/models/base.py", line 851, in _do_insert
    using=using, raw=raw)
  File "//anaconda/lib/python2.7/site-packages/django/db/models/manager.py", line 122, in manager_method
    return getattr(self.get_queryset(), name)(*args, **kwargs)
  File "//anaconda/lib/python2.7/site-packages/django/db/models/query.py", line 1039, in _insert
    return query.get_compiler(using=using).execute_sql(return_id)
  File "//anaconda/lib/python2.7/site-packages/django/db/models/sql/compiler.py", line 1060, in execute_sql
    cursor.execute(sql, params)
  File "//anaconda/lib/python2.7/site-packages/django/db/backends/utils.py", line 79, in execute
    return super(CursorDebugWrapper, self).execute(sql, params)
  File "//anaconda/lib/python2.7/site-packages/django/db/backends/utils.py", line 64, in execute
    return self.cursor.execute(sql, params)
  File "//anaconda/lib/python2.7/site-packages/django/db/utils.py", line 95, in __exit__
    six.reraise(dj_exc_type, dj_exc_value, traceback)
  File "//anaconda/lib/python2.7/site-packages/django/db/backends/utils.py", line 64, in execute
    return self.cursor.execute(sql, params)
  File "//anaconda/lib/python2.7/site-packages/django/db/backends/sqlite3/base.py", line 323, in execute
    return Database.Cursor.execute(self, query, params)
IntegrityError: NOT NULL constraint failed: vocab_worditem.person_id
2016-02-01 22:38:32,310::WARNING::base.py::182::[get_response(...)] :: Not Found: /favicon.ico
2016-02-01 22:38:34,635::WARNING::base.py::182::[get_response(...)] :: Not Found: /favicon.ico
2016-02-01 22:48:57,563::ERROR::base.py::284::[handle_uncaught_exception(...)] :: Internal Server Error: /quiz/FFPBYTJL/2
Traceback (most recent call last):
  File "//anaconda/lib/python2.7/site-packages/django/core/handlers/base.py", line 149, in get_response
    response = self.process_exception_by_middleware(e, request)
  File "//anaconda/lib/python2.7/site-packages/django/core/handlers/base.py", line 147, in get_response
    response = wrapped_callback(request, *callback_args, **callback_kwargs)
  File "/Users/kevindunn/Personal/Myself/Learn-Dutch/flashcards/vocab/views.py", line 348, in quiz_HTML
    person=person)[0]
  File "//anaconda/lib/python2.7/site-packages/django/db/models/query.py", line 297, in __getitem__
    return list(qs)[0]
IndexError: list index out of range
